Workbook

Sheet TS_DATA
A1: Campaign ID | B1: TS_Spend_20260426 | C1: TS_Spend_20260427 | D1: TS_Spend_20260428 | E1: TS_Spend_20260429 | F1: TS_Spend_20260430 | G1: TS_Spend_20260501 | H1: TS_Spend_20260502 | I1: TS_Spend_20260503 | J1: TS_Spend_20260504 | K1: TS_Spend_20260505 | L1: TS_Spend_20260506 | M1: TS_Spend_20260507 | N1: TS_Spend_20260508 | O1: TS_Spend_20260509 | P1: TS_Sales_20260426 | Q1: TS_Sales_20260427 | R1: TS_Sales_20260428 | S1: TS_Sales_20260429 | T1: TS_Sales_20260430 | U1: TS_Sales_20260501 | V1: TS_Sales_20260502 | W1: TS_Sales_20260503 | X1: TS_Sales_20260504 | Y1: TS_Sales_20260505 | Z1: TS_Sales_20260506 | AA1: TS_Sales_20260507 | AB1: TS_Sales_20260508 | AC1: TS_Sales_20260509
A2: 101488137797202 | B2: 0.14618894 | C2: 0.13629803 | D2: 0.00098526478 | E2: 0.099430086 | F2: 0.11920051 | G2: 0.15745016 | H2: 0.070406592 | I2: 0.065049415 | J2: 0.15389262 | K2: 0.056468022 | L2: 0.02259829 | M2: 0.037076715 | N2: 0.084162467 | O2: 0.14079289 | P2: 0 | Q2: 0 | R2: 0 | S2: 0 | T2: 0 | U2: 0 | V2: 0 | W2: 0 | X2: 0 | Y2: 0 | Z2: 0 | AA2: 0 | AB2: 0 | AC2: 0
A3: 101923312615244 | B3: 0.10726471 | C3: 0.01747156 | D3: 0.82815448 | E3: 1.0357373 | F3: 1.1898818 | G3: 1.7034849 | H3: 1.5445402 | I3: 0.32378185 | J3: 0.68896935 | K3: 0.77689619 | L3: 1.1518211 | M3: 1.0714316 | N3: 0.80713386 | O3: 1.4434311 | P3: 1.3258439 | Q3: 1.064161 | R3: 0.30396319 | S3: 0.72768825 | T3: 0.0088086246 | U3: 0.64484772 | V3: 1.3290588 | W3: 0.77841353 | X3: 0.84801106 | Y3: 0.11891003 | Z3: 0.82120775 | AA3: 0.90650204 | AB3: 0.24402123 | AC3: 0.85856284
A4: 102856384896731 | B4: 0.23527695 | C4: 0.54443345 | D4: 0.39947029 | E4: 0.37934877 | F4: 0.27832429 | G4: 0.46207138 | H4: 0.17689172 | I4: 0.19195287 | J4: 0.070027254 | K4: 0.2360298 | L4: 0.2601453 | M4: 0.53537815 | N4: 0.5778043 | O4: 0.45284547 | P4: 0 | Q4: 0 | R4: 0 | S4: 0 | T4: 0 | U4: 0 | V4: 0 | W4: 0 | X4: 0 | Y4: 0 | Z4: 0 | AA4: 0 | AB4: 0 | AC4: 0
A5: 105463042109939 | B5: 0.19583078 | C5: 0.022522076 | D5: 0.22443123 | E5: 0.078384074 | F5: 0.18539748 | G5: 0.026105061 | H5: 0.13809061 | I5: 0.014826003 | J5: 0.2658533 | K5: 0.082427213 | L5: 0.040439916 | M5: 0.085988444 | N5: 0.14863741 | O5: 0.1410664 | P5: 0 | Q5: 0 | R5: 0 | S5: 0 | T5: 0 | U5: 0 | V5: 0 | W5: 0 | X5: 0 | Y5: 0 | Z5: 0 | AA5: 0 | AB5: 0 | AC5: 0
A6: 105567346876487 | B6: 0.77177023 | C6: 0.60739871 | D6: 0.48708954 | E6: 1.0506588 | F6: 0.26202791 | G6: 0.13332256 | H6: 0.57221935 | I6: 0.71463999 | J6: 0.91477132 | K6: 0.30907781 | L6: 0.52073205 | M6: 0.1542297 | N6: 0.209751 | O6: 0.47231102 | P6: 0 | Q6: 0 | R6: 0 | S6: 0 | T6: 0 | U6: 0 | V6: 0 | W6: 0 | X6: 0 | Y6: 0 | Z6: 0 | AA6: 0 | AB6: 0 | AC6: 0
A7: 10813899667798 | B7: 0.048143314 | C7: 0.11032292 | D7: 0.17131314 | E7: 0.15124822 | F7: 0.22109633 | G7: 0.05167243 | H7: 0.08243799 | I7: 0.25328021 | J7: 0.2178872 | K7: 0.062559379 | L7: 0.070437535 | M7: 0.13671854 | N7: 0.29461777 | O7: 0.28826501 | P7: 0 | Q7: 0 | R7: 0 | S7: 0 | T7: 0 | U7: 0 | V7: 0 | W7: 0 | X7: 0 | Y7: 0 | Z7: 0 | AA7: 0 | AB7: 0 | AC7: 0
A8: 112042356340401 | B8: 0.030723086 | C8: 0.045388494 | D8: 0.023295993 | E8: 0.011334766 | F8: 0.01649845 | G8: 0.027246006 | H8: 0.042040719 | I8: 0.031663382 | J8: 0.002986815 | K8: 0.0054435954 | L8: 0.016750387 | M8: 0.028570255 | N8: 0.010045931 | O8: 0.038012121 | P8: 0 | Q8: 0 | R8: 0 | S8: 0 | T8: 0 | U8: 0 | V8: 0 | W8: 0 | X8: 0 | Y8: 0 | Z8: 0 | AA8: 0 | AB8: 0 | AC8: 0
A9: 112308637757247 | B9: 1.2295545 | C9: 1.0989351 | D9: 1.4538526 | E9: 0.67259258 | F9: 1.6138331 | G9: 1.3162981 | H9: 0.96276357 | I9: 1.5040421 | J9: 1.135939 | K9: 1.3365806 | L9: 0.094580904 | M9: 1.0957955 | N9: 0.93992604 | O9: 0.33530632 | P9: 1.7405569 | Q9: 3.2655534 | R9: 1.9880507 | S9: 0.47537976 | T9: 3.4525651 | U9: 2.5131073 | V9: 2.9701296 | W9: 3.7315076 | X9: 2.6848799 | Y9: 1.590309 | Z9: 2.8934446 | AA9: 0.9472305 | AB9: 0.4562137 | AC9: 1.231072
A10: 113302005833222 | B10: 1.2372165 | C10: 0.36718043 | D10: 1.3803732 | E10: 0.59986339 | F10: 0.44182093 | G10: 0.37736584 | H10: 1.1526568 | I10: 1.3616388 | J10: 0.11262606 | K10: 0.48767294 | L10: 0.93969789 | M10: 0.19007496 | N10: 0.73667031 | O10: 0.38514196 | P10: 0 | Q10: 0 | R10: 0 | S10: 0 | T10: 0 | U10: 0 | V10: 0 | W10: 0 | X10: 0 | Y10: 0 | Z10: 0 | AA10: 0 | AB10: 0 | AC10: 0
A11: 115136032504275 | B11: 0 | C11: 0 | D11: 0 | E11: 0 | F11: 0 | G11: 0 | H11: 0 | I11: 0 | J11: 0 | K11: 0 | L11: 0 | M11: 0 | N11: 0 | O11: 0 | P11: 0 | Q11: 0 | R11: 0 | S11: 0 | T11: 0 | U11: 0 | V11: 0 | W11: 0 | X11: 0 | Y11: 0 | Z11: 0 | AA11: 0 | AB11: 0 | AC11: 0
A12: 116356105692321 | B12: 0.62185045 | C12: 0.44731065 | D12: 0.37907981 | E12: 0.033426166 | F12: 0.63320303 | G12: 0.3058609 | H12: 0.35839663 | I12: 0.28627249 | J12: 0.71961624 | K12: 0.31386343 | L12: 0.45258886 | M12: 0.82896729 | N12: 0.081018626 | O12: 0.55854543 | P12: 1.6270717 | Q12: 1.3206001 | R12: 0.12173445 | S12: 0.40910344 | T12: 2.5083358 | U12: 1.6928322 | V12: 0.42124463 | W12: 1.0956469 | X12: 2.4709694 | Y12: 1.222508 | Z12: 1.7541418 | AA12: 2.4083561 | AB12: 1.7483791 | AC12: 1.1590765
A13: 116718529674254 | B13: 0.032376184 | C13: 0.18210699 | D13: 0.19072381 | E13: 0.063102814 | F13: 0.15971974 | G13: 0.0059362928 | H13: 0.082333251 | I13: 0.13854996 | J13: 0.0067030823 | K13: 0.039141051 | L13: 0.035313551 | M13: 0.026695128 | N13: 0.10384173 | O13: 0.18345642 | P13: 0 | Q13: 0 | R13: 0 | S13: 0 | T13: 0 | U13: 0 | V13: 0 | W13: 0 | X13: 0 | Y13: 0 | Z13: 0 | AA13: 0 | AB13: 0 | AC13: 0
... A152: 98819765609033 | B152: 2.0548977 | C152: 3.086943 | D152: 2.1028372 | E152: 2.6826827 | F152: 1.5844365 | G152: 2.6102604 | H152: 1.020762 | I152: 3.9698857 | J152: 0.74670936 | K152: 2.0141845 | L152: 1.2013348 | M152: 3.0499877 | N152: 3.1053834 | O152: 4.1996948 | P152: 3.4939502 | Q152: 3.5372817 | R152: 1.2841358 | S152: 3.9222464 | T152: 5.1981617 | U152: 1.1404639 | V152: 5.187529 | W152: 4.8749257 | X152: 4.0637428 | Y152: 0.15419814 | Z152: 1.0622464 | AA152: 0.21329338 | AB152: 4.2523891 | AC152: 3.5354357

Sheet 📊 OVERVIEW
B2: TỔNG QUAN TÀI KHOẢN
B4: Report Date | C4: 2026-05-10 17:43
B5: Total Campaigns | C5: 151
B6: Active Campaigns | C6: 151
B7: Total Keywords/Targets | C7: 920
B8: Total Spend | C8: 494.89
B9: Total Sales | C9: 670.6
B10: Total Orders | C10: 67
B11: Overall ACOS | C11: 0.73798091
B12: Overall ROAS | C12: 1.3550486

Sheet 🎯 CAMPAIGNS
A1: Campaign ID | B1: Campaign Name | C1: Portfolio Name (Informational only) | D1: State | E1: Targeting Type | F1: Bidding Strategy | G1: Daily Budget | H1: Campaign Age | I1: Lifecycle Phase | J1: Impressions | K1: Clicks | L1: Spend | M1: Sales | N1: Orders | O1: Units | P1: Click-through Rate | Q1: Conversion Rate | R1: ACOS | S1: CPC | T1: ROAS | U1: Health Tag | V1: 14-Day Spend Trend | W1: 14-Day Sales Trend
A2: 98819765609033 | B2: REWARDJAR_PT_reward jar for kid | C2: REWARD JAR_2026 | D2: enabled | E2: Manual | F2: Dynamic bids - down only | G2: 2 | H2: 33 | I2: Growth | J2: 3472 | K2: 65 | L2: 33.43 | M2: 41.92 | N2: 4 | O2: 4 | P2: 0.0187 | Q2: 0.06 | R2: 0.7975 | S2: 0.51 | T2: 1.25 | U2: 🔴 Bleeder
A3: 186731767495729 | B3: 250TH_DEVOM_DAIBANG1776-2026_KT_exact_4th of july decorations_35TRP | C3: 250th USA | D3: enabled | E3: Manual | F3: Dynamic bids - down only | G3: 2 | H3: 26 | I3: Launch | J3: 9022 | K3: 30 | L3: 29.13 | M3: 29.94 | N3: 3 | O3: 3 | P3: 0.0033 | Q3: 0.1 | R3: 0.9729 | S3: 0.97 | T3: 1.03 | U3: 🔴 Bleeder
A4: 69958337116340 | B4: MONEYHOLDER_SET3CARD_GAS_KTmoney gift ideas_ | C4: MONEY HOLDER | D4: enabled | E4: Manual | F4: Dynamic bids - down only | G4: 2 | H4: 28 | I4: Launch | J4: 4574 | K4: 63 | L4: 27.39 | M4: 35.94 | N4: 3 | O4: 3 | P4: 0.0138 | Q4: 0.05 | R4: 0.7621 | S4: 0.43 | T4: 1.31 | U4: 🔴 Bleeder
A5: 134389069964001 | B5: 250TH_STICKER_SET5_PT_Q | C5: 250th USA | D5: enabled | E5: Manual | F5: Dynamic bids - down only | G5: 2 | H5: 26 | I5: Launch | J5: 59519 | K5: 73 | L5: 26.4 | M5: 47.84 | N5: 8 | O5: 8 | P5: 0.0012 | Q5: 0.11 | R5: 0.5518 | S5: 0.36 | T5: 1.81 | U5: 🔴 Bleeder
A6: 369656292820642 | B6: SET3_GAS_011225 | C6: MONEY HOLDER | D6: enabled | E6: Manual | F6: Dynamic bids - down only | G6: 2 | H6: 160 | I6: Mature/Dormant | J6: 2853 | K6: 56 | L6: 19.74 | M6: 95.84 | N6: 8 | O6: 8 | P6: 0.0196 | Q6: 0.14 | R6: 0.206 | S6: 0.35 | T6: 4.86 | U6: ⭐ Star
A7: 235237638638785 | B7: ONM_250TH_CHUONG_PT | C7: 250th USA | D7: enabled | E7: Manual | F7: Dynamic bids - up and down | G7: 2 | H7: 47 | I7: Growth | J7: 926 | K7: 26 | L7: 19.41 | M7: 47.9 | N7: 3 | O7: 7 | P7: 0.0281 | Q7: 0.12 | R7: 0.4052 | S7: 0.75 | T7: 2.47 | U7: 🔴 Bleeder
A8: 198663511897772 | B8: 250TH_DEVOM_DAIBANG1776-2026_KT_ALL_decor | C8: 250th USA | D8: enabled | E8: Manual | F8: Dynamic bids - down only | G8: 2 | H8: 30 | I8: Growth | J8: 7689 | K8: 25 | L8: 16.19 | M8: 59.88 | N8: 6 | O8: 6 | P8: 0.0033 | Q8: 0.24 | R8: 0.2704 | S8: 0.65 | T8: 3.7 | U8: ⚠️ Watch
A9: 227286038709324 | B9: 250TH_STICKER_SET5_KT_RANK_STIKER | C9: 250th USA | D9: enabled | E9: Manual | F9: Dynamic bids - down only | G9: 2 | H9: 28 | I9: Launch | J9: 2287 | K9: 25 | L9: 15.05 | M9: 5.98 | N9: 1 | O9: 1 | P9: 0.0109 | Q9: 0.04 | R9: 2.5167 | S9: 0.6 | T9: 0.4 | U9: 🔴 Bleeder
A10: 112308637757247 | B10: MONEYHOLDER_GRADUATION2026_KT_ALL_EX_graduation money holder | C10: GRADUATION2026 | D10: enabled | E10: Manual | F10: Dynamic bids - down only | G10: 2 | H10: 31 | I10: Seasonal (Peak/Pre/Post) | J10: 1433 | K10: 17 | L10: 14.79 | M10: 29.94 | N10: 2 | O10: 3 | P10: 0.0119 | Q10: 0.12 | R10: 0.494 | S10: 0.87 | T10: 2.02 | U10: 🔴 Bleeder
A11: 352883383901680 | B11: ONM_HUMMINGBIRD_PT_HMB_161025 | C11: B0FS1NRM82- ONM_HUMMINGBIRD | D11: enabled | E11: Manual | F11: Dynamic bids - down only | G11: 2 | H11: 206 | I11: Mature/Dormant | J11: 1332 | K11: 47 | L11: 13.35 | M11: 39.9 | N11: 4 | O11: 5 | P11: 0.0353 | Q11: 0.09 | R11: 0.3346 | S11: 0.28 | T11: 2.99 | U11: ⚠️ Watch
A12: 244822658128222 | B12: MONEYHOLDER_GRADUATION2026_KT_graduation money gift ideas | C12: GRADUATION2026 | D12: enabled | E12: Manual | F12: Dynamic bids - down only | G12: 2 | H12: 28 | I12: Seasonal (Peak/Pre/Post) | J12: 1809 | K12: 19 | L12: 12.72 | M12: 9.98 | N12: 1 | O12: 1 | P12: 0.0105 | Q12: 0.05 | R12: 1.2745 | S12: 0.67 | T12: 0.78 | U12: 🔴 Bleeder
A13: 101923312615244 | B13: MONEYHOLDER_GRADUATION2026_KT_EX_graduation cards 2026 | C13: GRADUATION2026 | D13: enabled | E13: Manual | F13: Dynamic bids - down only | G13: 2 | H13: 30 | I13: Seasonal (Peak/Pre/Post) | J13: 4170 | K13: 16 | L13: 12.69 | M13: 9.98 | N13: 1 | O13: 1 | P13: 0.0038 | Q13: 0.06 | R13: 1.2715 | S13: 0.79 | T13: 0.79 | U13: 🔴 Bleeder
... A48: 46172503474884 | B48: 250TH_DEVOM_DAIBANG1776-2026_KT_broad_4th of july decorations_35TRP | C48: 250th USA | D48: enabled | E48: Manual | F48: Dynamic bids - down only | G48: 2 | H48: 26 | I48: Launch | J48: 278 | K48: 3 | L48: 1.9 | M48: 9.98 | N48: 1 | O48: 1 | P48: 0.0108 | Q48: 0.33 | R48: 0.1904 | S48: 0.63 | T48: 5.25 | U48: 🆕 New
A49: 250843173848396 | B49: 250TH_DEVOM_DAIBANG1776-2026_AUTO | D49: enabled | E49: Auto | F49: Dynamic bids - down only | G49: 2 | H49: 30 | I49: Growth | J49: 513 | K49: 4 | L49: 1.8 | M49: 0 | N49: 0 | O49: 0 | P49: 0.0078 | Q49: 0 | R49: 0 | S49: 0.45 | T49: 0 | U49: 🆕 New
A50: 105463042109939 | B50: AD_READY: B0GV363VR9 | C50: MOTHER DAY 2026 | D50: enabled | E50: Manual | F50: Dynamic bids - down only | G50: 2 | H50: 33 | I50: Growth | J50: 552 | K50: 3 | L50: 1.65 | M50: 0 | N50: 0 | O50: 0 | P50: 0.0054 | Q50: 0 | R50: 0 | S50: 0.55 | T50: 0 | U50: 🆕 New
A51: 228866773120740 | B51: 250TH_STICKER_KT_USA 250th Anniversary Sticker | C51: 250th USA | D51: enabled | E51: Manual | F51: Dynamic bids - down only | G51: 5.6 | H51: 33 | I51: Growth | J51: 636 | K51: 3 | L51: 1.64 | M51: 0 | N51: 0 | O51: 0 | P51: 0.0047 | Q51: 0 | R51: 0 | S51: 0.55 | T51: 0 | U51: 🆕 New
A52: 193015945118300 | B52: 250TH_DEVOM_DAIBANG1776-2026_KT_phrase_4th of july decorations_35TRP | C52: 250th USA | D52: enabled | E52: Manual | F52: Dynamic bids - down only | G52: 2 | H52: 26 | I52: Launch | J52: 831 | K52: 2 | L52: 1.62 | M52: 0 | N52: 0 | O52: 0 | P52: 0.0024 | Q52: 0 | R52: 0 | S52: 0.81 | T52: 0 | U52: 🆕 New
A53: 194634584973962 | B53: 250TH_DEVOM_DAIBANG1776-2026_KT_broad_patriotic decor_35TRP | C53: 250th USA | D53: enabled | E53: Manual | F53: Dynamic bids - down only | G53: 5.6 | H53: 26 | I53: Launch | J53: 295 | K53: 3 | L53: 1.56 | M53: 9.98 | N53: 1 | O53: 1 | P53: 0.0102 | Q53: 0.33 | R53: 0.1563 | S53: 0.52 | T53: 6.4 | U53: 🆕 New
A54: 553683809238822 | B54: ONM_FUNNYSANTA_01_KT_SKIBIDI | C54: Parent ASIN: B0G2BZCBKK_SANTA67 | D54: enabled | E54: Manual | F54: Dynamic bids - down only | G54: 2 | H54: 164 | I54: Mature/Dormant | J54: 176 | K54: 2 | L54: 1.36 | M54: 0 | N54: 0 | O54: 0 | P54: 0.0114 | Q54: 0 | R54: 0 | S54: 0.68 | T54: 0 | U54: 🆕 New
A55: 224347910621901 | B55: 250TH_DEVOM_DAIBANG1776-2026_KT_broad_4th of july table runner_35TRP | C55: 250th USA | D55: enabled | E55: Manual | F55: Dynamic bids - down only | G55: 5 | H55: 26 | I55: Launch | J55: 209 | K55: 2 | L55: 1.34 | M55: 0 | N55: 0 | O55: 0 | P55: 0.0096 | Q55: 0 | R55: 0 | S55: 0.67 | T55: 0 | U55: 🆕 New
A56: 101488137797202 | B56: MONEYHOLDER_GRADUATION2026_KT_Phrase_2026 graduation gifts | C56: GRADUATION2026 | D56: enabled | E56: Manual | F56: Dynamic bids - down only | G56: 2 | H56: 30 | I56: Seasonal (Peak/Pre/Post) | J56: 98 | K56: 2 | L56: 1.29 | M56: 0 | N56: 0 | O56: 0 | P56: 0.0204 | Q56: 0 | R56: 0 | S56: 0.64 | T56: 0 | U56: 😴 Sleep
A57: 275329148889315 | B57: 250TH_2PCS_STICKER_KT_exact_patriotic stickers_30TRP | C57: 250th USA | D57: enabled | E57: Manual | F57: Dynamic bids - down only | G57: 2 | H57: 23 | I57: Launch | J57: 39 | K57: 2 | L57: 1.26 | M57: 0 | N57: 0 | O57: 0 | P57: 0.0513 | Q57: 0 | R57: 0 | S57: 0.63 | T57: 0 | U57: 😴 Sleep
A58: 116718529674254 | B58: AD_READY: B0GV3WBZJB | C58: MOTHER DAY 2026 | D58: enabled | E58: Manual | F58: Dynamic bids - down only | G58: 2 | H58: 33 | I58: Growth | J58: 139 | K58: 3 | L58: 1.25 | M58: 0 | N58: 0 | O58: 0 | P58: 0.0216 | Q58: 0 | R58: 0 | S58: 0.42 | T58: 0 | U58: 🆕 New
A59: 17275150993527 | B59: REWARDJAR_MIX2026_KT_ALLSG | C59: REWARD JAR_2026 | D59: enabled | E59: Manual | F59: Dynamic bids - down only | G59: 2 | H59: 51 | I59: Growth | J59: 258 | K59: 4 | L59: 1.17 | M59: 0 | N59: 0 | O59: 0 | P59: 0.0155 | Q59: 0 | R59: 0 | S59: 0.29 | T59: 0 | U59: 🆕 New
A60: 281412121777745 | B60: MONEYHOLDER_GRADUATION2026_KT_Phrase_2026 grad | C60: GRADUATION2026 | D60: enabled | E60: Manual | F60: Dynamic bids - down only | G60: 2 | H60: 30 | I60: Seasonal (Peak/Pre/Post) | J60: 383 | K60: 2 | L60: 1.14 | M60: 0 | N60: 0 | O60: 0 | P60: 0.0052 | Q60: 0 | R60: 0 | S60: 0.57 | T60: 0 | U60: 🆕 New
A61: 173085304045846 | B61: REWARDJAR_MIX2026_Auto | C61: REWARD JAR_2026 | D61: enabled | E61: Auto | F61: Dynamic bids - down only | G61: 2 | H61: 52 | I61: Growth | J61: 295 | K61: 3 | L61: 1.02 | M61: 0 | N61: 0 | O61: 0 | P61: 0.0102 | Q61: 0 | R61: 0 | S61: 0.34 | T61: 0 | U61: 🆕 New
... A71: 159392490976171 | B71: 250TH_2PCS_STICKER_KT_exact_250 anniversary usa stickers_30TRP | C71: 250th USA | D71: enabled | E71: Manual | F71: Dynamic bids - down only | G71: 2 | H71: 23 | I71: Launch | J71: 110 | K71: 1 | L71: 0.65 | M71: 0 | N71: 0 | O71: 0 | P71: 0.0091 | Q71: 0 | R71: 0 | S71: 0.65 | T71: 0 | U71: 🆕 New
A72: 529478061546487 | B72: ONM_SANTA67_KT_111225 | D72: enabled | E72: Manual | F72: Dynamic bids - down only | G72: 2 | H72: 150 | I72: Mature/Dormant | J72: 350 | K72: 1 | L72: 0.56 | M72: 0 | N72: 0 | O72: 0 | P72: 0.0029 | Q72: 0 | R72: 0 | S72: 0.56 | T72: 0 | U72: 🆕 New
A73: 465144980667508 | B73: ONM67_KT | C73: Parent ASIN: B0G2BZCBKK_SANTA67 | D73: enabled | E73: Manual | F73: Dynamic bids - down only | G73: 2 | H73: 145 | I73: Mature/Dormant | J73: 91 | K73: 1 | L73: 0.46 | M73: 0 | N73: 0 | O73: 0 | P73: 0.011 | Q73: 0 | R73: 0 | S73: 0.46 | T73: 0 | U73: 😴 Sleep
A74: 112042356340401 | B74: CARDMOTHERDAY_AUTO | C74: MOTHER DAY 2026 | D74: enabled | E74: Auto | F74: Dynamic bids - down only | G74: 2 | H74: 30 | I74: Seasonal (Peak/Pre/Post) | J74: 18 | K74: 1 | L74: 0.33 | M74: 0 | N74: 0 | O74: 0 | P74: 0.0556 | Q74: 0 | R74: 0 | S74: 0.33 | T74: 0 | U74: 😴 Sleep
A75: 469521778483198 | B75: ONM_THREETREE_KT_ALLSG | C75: Parent ASIN: B0G29ZR9FB_FRIEND_HLG_BABY | D75: enabled | E75: Manual | F75: Dynamic bids - down only | G75: 2 | H75: 171 | I75: Mature/Dormant | J75: 85 | K75: 1 | L75: 0.3 | M75: 0 | N75: 0 | O75: 0 | P75: 0.0118 | Q75: 0 | R75: 0 | S75: 0.3 | T75: 0 | U75: 😴 Sleep
A76: 225363350177497 | B76: MOTHERDAY_SIGN_TOMYMOM_KT_BR_Tier1_2 | C76: MOTHER DAY 2026 | D76: enabled | E76: Manual | F76: Dynamic bids - down only | G76: 2 | H76: 31 | I76: Seasonal (Peak/Pre/Post) | J76: 6 | K76: 1 | L76: 0.3 | M76: 0 | N76: 0 | O76: 0 | P76: 0.1667 | Q76: 0 | R76: 0 | S76: 0.3 | T76: 0 | U76: 😴 Sleep
A77: 41322192463517 | B77: 250TH_DEVOM_DAIBANG1776-2026_KT_exact_patriotic decor_35TRP | C77: 250th USA | D77: enabled | E77: Manual | F77: Dynamic bids - down only | G77: 2 | H77: 26 | I77: Launch | J77: 280 | K77: 0 | L77: 0 | M77: 0 | N77: 0 | O77: 0 | P77: 0 | Q77: 0 | R77: 0 | S77: 0 | T77: 0 | U77: 🆕 New
A78: 191924308931530 | B78: 250TH_DEVOM_DAIBANG1776-2026_KT_exact_patriotic decorations_35TRP | C78: 250th USA | D78: enabled | E78: Manual | F78: Dynamic bids - down only | G78: 5 | H78: 26 | I78: Launch | J78: 356 | K78: 0 | L78: 0 | M78: 0 | N78: 0 | O78: 0 | P78: 0 | Q78: 0 | R78: 0 | S78: 0 | T78: 0 | U78: 🆕 New
A79: 409253869409550 | B79: SANTASIXSEVEN_KW | C79: Parent ASIN: B0G2BZCBKK_SANTA67 | D79: enabled | E79: Manual | F79: Dynamic bids - down only | G79: 2 | H79: 173 | I79: Mature/Dormant | J79: 142 | K79: 0 | L79: 0 | M79: 0 | N79: 0 | O79: 0 | P79: 0 | Q79: 0 | R79: 0 | S79: 0 | T79: 0 | U79: 🆕 New
A80: 208854747643984 | B80: MONEYHOLDER_GRADUATION2026_KT_Phrase_class of 2026 gifts | C80: GRADUATION2026 | D80: enabled | E80: Manual | F80: Dynamic bids - down only | G80: 2 | H80: 30 | I80: Seasonal (Peak/Pre/Post) | J80: 127 | K80: 0 | L80: 0 | M80: 0 | N80: 0 | O80: 0 | P80: 0 | Q80: 0 | R80: 0 | S80: 0 | T80: 0 | U80: 🆕 New
A81: 204074438268263 | B81: 250TH_DEVOM_DAIBANG1776-2026_KT_phrase_fourth of july decorations_35TRP | C81: 250th USA | D81: enabled | E81: Manual | F81: Dynamic bids - down only | G81: 5 | H81: 26 | I81: Launch | J81: 105 | K81: 0 | L81: 0 | M81: 0 | N81: 0 | O81: 0 | P81: 0 | Q81: 0 | R81: 0 | S81: 0 | T81: 0 | U81: 🆕 New
A82: 345057303252833 | B82: B0FS1THWPG_ONM_2PCS-ELEPHANT_SP_KWALLSG-0.3_081025 | C82: Parent ASIN: B0G3WYDJHP_DRAGONFLYTREE_BOOKTRE_ISS_NATIVITY | D82: enabled | E82: Manual | F82: Dynamic bids - down only | G82: 1.6 | H82: 214 | I82: Mature/Dormant | J82: 104 | K82: 0 | L82: 0 | M82: 0 | N82: 0 | O82: 0 | P82: 0 | Q82: 0 | R82: 0 | S82: 0 | T82: 0 | U82: 🆕 New
A83: 540608473111064 | B83: ONM_TREE-DRAGONFLY_PT_Dragonfly onm | C83: Parent ASIN: B0G3WYDJHP_DRAGONFLYTREE_BOOKTRE_ISS_NATIVITY | D83: enabled | E83: Manual | F83: Dynamic bids - down only | G83: 2 | H83: 201 | I83: Mature/Dormant | J83: 131 | K83: 0 | L83: 0 | M83: 0 | N83: 0 | O83: 0 | P83: 0 | Q83: 0 | R83: 0 | S83: 0 | T83: 0 | U83: 🆕 New
...

Sheet 🔑 KEYWORDS
A1: Campaign ID | B1: Campaign Name (Informational only) | C1: Ad Group Name (Informational only) | D1: Portfolio Name (Informational only) | E1: Keyword / Target | F1: Match Type | G1: State | H1: Bid | I1: Lifecycle Phase | J1: Impressions | K1: Clicks | L1: Spend | M1: Sales | N1: Orders | O1: Click-through Rate | P1: Conversion Rate | Q1: ACOS | R1: CPC | S1: ROAS | T1: Health Tag | U1: Suggested Action
A2: 98819765609033 | B2: REWARDJAR_PT_reward jar for kid | C2: Ad Group - 4/7/2026 16:29:01.482 | D2: REWARD JAR_2026 | E2: category="1069080" | G2: enabled | H2: 0.5 | I2: Growth | J2: 3585 | K2: 66 | L2: 33.05 | M2: 41.92 | N2: 4 | O2: 0.0184 | P2: 0.06 | Q2: 0.7884 | R2: 0.5 | S2: 1.27 | T2: 🔴 Bleeder | U2: 📉 Decrease Bid
A3: 186731767495729 | B3: 250TH_DEVOM_DAIBANG1776-2026_KT_exact_4th of july decorations_35TRP | C3: 4th of july decorations | D3: 250th USA | E3: 4th of july decorations | F3: Exact | G3: enabled | H3: 0.76 | I3: Launch | J3: 9061 | K3: 30 | L3: 29.13 | M3: 29.94 | N3: 3 | O3: 0.0033 | P3: 0.1 | Q3: 0.9729 | R3: 0.97 | S3: 1.03 | T3: 🔴 Bleeder | U3: 📉 Decrease Bid
A4: 69958337116340 | B4: MONEYHOLDER_SET3CARD_GAS_KTmoney gift ideas_ | C4: Ad Group - 4/13/2026 09:07:09.624 | D4: MONEY HOLDER | E4: money gift ideas | F4: Broad | G4: enabled | H4: 0.37 | I4: Launch | J4: 3312 | K4: 55 | L4: 22.68 | M4: 23.96 | N4: 2 | O4: 0.0166 | P4: 0.04 | Q4: 0.9466 | R4: 0.41 | S4: 1.06 | T4: 🔴 Bleeder | U4: 📉 Decrease Bid
A5: 134389069964001 | B5: 250TH_STICKER_SET5_PT_Q | C5: Ad Group - 4/14/2026 17:56:55.150 | D5: 250th USA | E5: category="23575408011" | G5: paused | H5: 0.5 | I5: Launch | J5: 59382 | K5: 68 | L5: 22.5 | M5: 29.9 | N5: 5 | O5: 0.0011 | P5: 0.07 | Q5: 0.7525 | R5: 0.33 | S5: 1.33 | T5: 🔴 Bleeder | U5: 📉 Decrease Bid
A6: 101923312615244 | B6: MONEYHOLDER_GRADUATION2026_KT_EX_graduation cards 2026 | C6: graduation cards 2026 | D6: GRADUATION2026 | E6: graduation cards 2026 | F6: Exact | G6: enabled | H6: 0.66 | I6: Seasonal (Peak/Pre/Post) | J6: 4171 | K6: 16 | L6: 12.69 | M6: 9.98 | N6: 1 | O6: 0.0038 | P6: 0.06 | Q6: 1.2715 | R6: 0.79 | S6: 0.79 | T6: 🔴 Bleeder | U6: 📉 Decrease Bid
A7: 238545012850995 | B7: REWARDJAR_MIX2026_reward jar | C7: Ad Group - 3/23/2026 11:42:59.947 | D7: REWARD JAR_2026 | E7: reward jar | F7: Exact | G7: enabled | H7: 0.78 | I7: Growth | J7: 1608 | K7: 14 | L7: 11.58 | M7: 23.96 | N7: 2 | O7: 0.0087 | P7: 0.14 | Q7: 0.4833 | R7: 0.83 | S7: 2.07 | T7: 🔴 Bleeder | U7: 📉 Decrease Bid
A8: 227286038709324 | B8: 250TH_STICKER_SET5_KT_RANK_STIKER | C8: Ad Group - 4/13/2026 10:11:28.979 | D8: 250th USA | E8: 250 anniversary usa stickers | F8: Phrase | G8: enabled | H8: 0.52 | I8: Launch | J8: 1569 | K8: 18 | L8: 10.87 | M8: 5.98 | N8: 1 | O8: 0.0115 | P8: 0.06 | Q8: 1.8177 | R8: 0.6 | S8: 0.55 | T8: 🔴 Bleeder | U8: 📉 Decrease Bid
A9: 240427188289432 | B9: MONEYHOLDER_GRADUATION2026_KT_Phrase_graduation gifts | C9: graduation gifts | D9: GRADUATION2026 | E9: graduation gifts | F9: Phrase | G9: enabled | H9: 0.56 | I9: Seasonal (Peak/Pre/Post) | J9: 2239 | K9: 20 | L9: 10.7 | M9: 0 | N9: 0 | O9: 0.0089 | P9: 0 | Q9: 0 | R9: 0.53 | S9: 0 | T9: 💀 Dead | U9: ⏸️ Pause
A10: 244822658128222 | B10: MONEYHOLDER_GRADUATION2026_KT_graduation money gift ideas | C10: Ad Group - 4/13/2026 09:30:34.907 | D10: GRADUATION2026 | E10: graduation money gift ideas | F10: Broad | G10: enabled | H10: 0.45 | I10: Seasonal (Peak/Pre/Post) | J10: 1355 | K10: 16 | L10: 10.02 | M10: 9.98 | N10: 1 | O10: 0.0118 | P10: 0.06 | Q10: 1.004 | R10: 0.63 | S10: 1 | T10: 🔴 Bleeder | U10: 📉 Decrease Bid
A11: 113302005833222 | B11: MONEYHOLDER_GRADUATION2026_KT_EX_graduation gifts for him | C11: graduation gifts for him | D11: GRADUATION2026 | E11: graduation gifts for him | F11: Exact | G11: enabled | H11: 0.66 | I11: Seasonal (Peak/Pre/Post) | J11: 1229 | K11: 12 | L11: 9.77 | M11: 0 | N11: 0 | O11: 0.0098 | P11: 0 | Q11: 0 | R11: 0.81 | S11: 0 | T11: 🆕 New | U11: 👀 Monitor
A12: 369656292820642 | B12: SET3_GAS_011225 | C12: Ad Group - 12/1/2025 17:27:55.919 | D12: MONEY HOLDER | E12: gas cards | F12: Phrase | G12: enabled | H12: 0.45 | I12: Mature/Dormant | J12: 1029 | K12: 24 | L12: 9.76 | M12: 23.96 | N12: 2 | O12: 0.0233 | P12: 0.08 | Q12: 0.4073 | R12: 0.41 | S12: 2.45 | T12: 🔴 Bleeder | U12: 📉 Decrease Bid
A13: 204816504612510 | B13: MOTHERDAY_SIGN_TOMYMOM_KT_PR_mother day decorations | C13: MOTHERDAY_SIGN_TOMYMOM | D13: MOTHER DAY 2026 | E13: mother day decorations | F13: Phrase | G13: enabled | H13: 0.68 | I13: Seasonal (Peak/Pre/Post) | J13: 509 | K13: 12 | L13: 9.34 | M13: 0 | N13: 0 | O13: 0.0236 | P13: 0 | Q13: 0 | R13: 0.78 | S13: 0 | T13: 🆕 New | U13: 👀 Monitor
A14: 112308637757247 | B14: MONEYHOLDER_GRADUATION2026_KT_ALL_EX_graduation money holder | C14: Ad Group - 4/10/2026 10:08:29.412 | D14: GRADUATION2026 | E14: graduation money holders | F14: Exact | G14: enabled | H14: 0.7 | I14: Seasonal (Peak/Pre/Post) | J14: 704 | K14: 10 | L14: 8.86 | M14: 9.98 | N14: 1 | O14: 0.0142 | P14: 0.1 | Q14: 0.8878 | R14: 0.89 | S14: 1.13 | T14: 🔴 Bleeder | U14: 📉 Decrease Bid
A15: 235237638638785 | B15: ONM_250TH_CHUONG_PT | C15: Ad Group - 3/25/2026 09:13:17.173 | D15: 250th USA | E15: asin="B0G24N6CKX" | G15: enabled | H15: 0.45 | I15: Growth | J15: 473 | K15: 11 | L15: 8.52 | M15: 0 | N15: 0 | O15: 0.0233 | P15: 0 | Q15: 0 | R15: 0.77 | S15: 0 | T15: 🆕 New | U15: 👀 Monitor
A16: 225195365697921 | B16: REWARDJAR_MIX2026_reward jars for kids | C16: Ad Group - 3/19/2026 16:06:24.106 | D16: REWARD JAR_2026 | E16: reward jars for kids | F16: Exact | G16: enabled | H16: 0.6 | I16: Growth | J16: 1996 | K16: 12 | L16: 7.2 | M16: 0 | N16: 0 | O16: 0.006 | P16: 0 | Q16: 0 | R16: 0.6 | S16: 0 | T16: 🆕 New | U16: 👀 Monitor
A17: 105567346876487 | B17: MONEYHOLDER_GRADUATION2026_KT_EX_2026 graduation gifts | C17: 2026 graduation gifts | D17: GRADUATION2026 | E17: 2026 graduation gifts | F17: Exact | G17: enabled | H17: 0.66 | I17: Seasonal (Peak/Pre/Post) | J17: 480 | K17: 9 | L17: 7.18 | M17: 0 | N17: 0 | O17: 0.0188 | P17: 0 | Q17: 0 | R17: 0.8 | S17: 0 | T17: 🆕 New | U17: 👀 Monitor
A18: 33235065457583 | B18: ALLCARDMOTHERDAY_KT_card | C18: Ad Group - 4/13/2026 16:42:30.843 | D18: MOTHER DAY 2026 | E18: mothers day card | F18: Broad | G18: enabled | H18: 0.56 | I18: Seasonal (Peak/Pre/Post) | J18: 940 | K18: 13 | L18: 7.03 | M18: 0 | N18: 0 | O18: 0.0138 | P18: 0 | Q18: 0 | R18: 0.54 | S18: 0 | T18: 🆕 New | U18: 👀 Monitor
A19: 216904671554832 | B19: MONEYHOLDER_GRADUATION2026_KT_ALL_PR_graduation money holder | C19: Ad Group - 4/10/2026 10:16:49.564 | D19: GRADUATION2026 | E19: graduation money | F19: Phrase | G19: enabled | H19: 0.5 | I19: Seasonal (Peak/Pre/Post) | J19: 1140 | K19: 12 | L19: 6.82 | M19: 0 | N19: 0 | O19: 0.0105 | P19: 0 | Q19: 0 | R19: 0.57 | S19: 0 | T19: 🆕 New | U19: 👀 Monitor
A20: 502767062906913 | B20: ONM_HUMMINGBIRD_KT-HMB_EXR_161025 | C20: Ad Group - 10/16/2025 15:47:43.916 | D20: B0FS1NRM82- ONM_HUMMINGBIRD | E20: hummingbird ornament | F20: Exact | G20: enabled | H20: 0.51 | I20: Mature/Dormant | J20: 1513 | K20: 14 | L20: 6.74 | M20: 7.98 | N20: 1 | O20: 0.0093 | P20: 0.07 | Q20: 0.8446 | R20: 0.48 | S20: 1.18 | T20: 🔴 Bleeder | U20: 📉 Decrease Bid
A21: 116356105692321 | B21: 250TH_DEVOM_DAIBANG1776-2026_KT_broad_patriotic decorations_35TRP | C21: patriotic decorations | D21: 250th USA | E21: patriotic decorations | F21: Broad | G21: enabled | H21: 0.5 | I21: Launch | J21: 1680 | K21: 10 | L21: 6.69 | M21: 19.96 | N21: 2 | O21: 0.006 | P21: 0.2 | Q21: 0.3352 | R21: 0.67 | S21: 2.98 | T21: ⚠️ Watch | U21: 👀 Monitor
A22: 9576707159426 | B22: 250TH_DEVOM_DAIBANG1776-2026_KT_exact_250 anniversary usa merchandise_35TRP | C22: 250 anniversary usa merchandise | D22: 250th USA | E22: 250 anniversary usa merchandise | F22: Exact | G22: enabled | H22: 0.8 | I22: Launch | J22: 2890 | K22: 7 | L22: 6.51 | M22: 19.96 | N22: 2 | O22: 0.0024 | P22: 0.29 | Q22: 0.3262 | R22: 0.93 | S22: 3.07 | T22: ⚠️ Watch | U22: 👀 Monitor
A23: 406223460061520 | B23: CROSSCAR_PSALM9111_KT_ALLGENERIC_101125 | C23: Ad Group - 11/10/2025 16:39:21.661 | D23: CROSS CAR | E23: christian car cross | F23: Broad | G23: enabled | H23: 0.4 | I23: Mature/Dormant | J23: 540 | K23: 14 | L23: 6.51 | M23: 15.96 | N23: 2 | O23: 0.0259 | P23: 0.14 | Q23: 0.4079 | R23: 0.46 | S23: 2.45 | T23: 🔴 Bleeder | U23: 📉 Decrease Bid
A24: 14636266059619 | B24: 250TH_STICKER_SET5_KT_Q | C24: Ad Group - 4/14/2026 17:54:19.571 | D24: 250th USA | E24: usa stickers | F24: Exact | G24: enabled | H24: 0.68 | I24: Launch | J24: 862 | K24: 9 | L24: 6.33 | M24: 0 | N24: 0 | O24: 0.0104 | P24: 0 | Q24: 0 | R24: 0.7 | S24: 0 | T24: 🆕 New | U24: 👀 Monitor
A25: 246552225706529 | B25: 250TH_auto | C25: Ad Group - 3/20/2026 15:54:48.919 | D25: 250th USA | E25: substitutes | G25: enabled | H25: 0 | I25: Growth | J25: 624 | K25: 17 | L25: 5.95 | M25: 15.96 | N25: 2 | O25: 0.0272 | P25: 0.12 | Q25: 0.3728 | R25: 0.35 | S25: 2.68 | T25: ⚠️ Watch | U25: 👀 Monitor
A26: 58528941976065 | B26: AD_READY: B0GV3ZPDK8 | C26: Ad group - 4/7/2026 16:37:45.293 | D26: MOTHER DAY 2026 | E26: birthday card | F26: Broad | G26: enabled | H26: 0.45 | I26: Growth | J26: 418 | K26: 12 | L26: 5.26 | M26: 0 | N26: 0 | O26: 0.0287 | P26: 0 | Q26: 0 | R26: 0.44 | S26: 0 | T26: 🆕 New | U26: 👀 Monitor
A27: 102856384896731 | B27: MOTHERDAY_SIGN_TOMYMOM_KT_PR_ALL_Mom | C27: MOTHERDAY_SIGN_TOMYMOM | D27: MOTHER DAY 2026 | E27: for mom | F27: Phrase | G27: enabled | H27: 0.5 | I27: Seasonal (Peak/Pre/Post) | J27: 673 | K27: 9 | L27: 4.92 | M27: 0 | N27: 0 | O27: 0.0134 | P27: 0 | Q27: 0 | R27: 0.55 | S27: 0 | T27: 🆕 New | U27: 👀 Monitor
A28: 69958337116340 | B28: MONEYHOLDER_SET3CARD_GAS_KTmoney gift ideas_ | C28: Ad Group - 4/13/2026 09:07:09.624 | D28: MONEY HOLDER | E28: money gift ideas | F28: Exact | G28: enabled | H28: 0.5 | I28: Launch | J28: 1451 | K28: 9 | L28: 4.83 | M28: 11.98 | N28: 1 | O28: 0.0062 | P28: 0.11 | Q28: 0.4032 | R28: 0.54 | S28: 2.48 | T28: 🔴 Bleeder | U28: 📉 Decrease Bid
A29: 235237638638785 | B29: ONM_250TH_CHUONG_PT | C29: Ad Group - 3/25/2026 09:13:17.173 | D29: 250th USA | E29: asin="B0G364W22F" | G29: enabled | H29: 0.45 | I29: Growth | J29: 147 | K29: 6 | L29: 4.79 | M29: 41.91 | N29: 2 | O29: 0.0408 | P29: 0.33 | Q29: 0.1143 | R29: 0.8 | S29: 8.75 | T29: 🆕 New | U29: 📈 Increase Bid
A30: 202664057560253 | B30: MONEYHOLDER_GRADUATION2026_AUTO | C30: Ad Group - 4/10/2026 10:10:59.421 | D30: GRADUATION2026 | E30: complements | G30: enabled | H30: 0 | I30: Seasonal (Peak/Pre/Post) | J30: 669 | K30: 11 | L30: 4.61 | M30: 0 | N30: 0 | O30: 0.0164 | P30: 0 | Q30: 0 | R30: 0.42 | S30: 0 | T30: 🆕 New | U30: 👀 Monitor
A31: 224300073021687 | B31: 250TH_STICKER_KT_sticker | C31: Ad Group - 4/10/2026 14:54:33.468 | D31: 250th USA | E31: bumper stickers | F31: Phrase | G31: enabled | H31: 0.35 | I31: Growth | J31: 2971 | K31: 9 | L31: 4.15 | M31: 7.98 | N31: 1 | O31: 0.003 | P31: 0.11 | Q31: 0.5201 | R31: 0.46 | S31: 1.92 | T31: 🔴 Bleeder | U31: 📉 Decrease Bid
A32: 369656292820642 | B32: SET3_GAS_011225 | C32: Ad Group - 12/1/2025 17:27:55.919 | D32: MONEY HOLDER | E32: gas gift card | F32: Phrase | G32: enabled | H32: 0.45 | I32: Mature/Dormant | J32: 917 | K32: 14 | L32: 4.07 | M32: 23.96 | N32: 2 | O32: 0.0153 | P32: 0.14 | Q32: 0.1699 | R32: 0.29 | S32: 5.89 | T32: 🆕 New | U32: 📈 Increase Bid
A33: 158911735804310 | B33: MONEYHOLDER_GRADUATION2026_KT_Phrase_graduation cards 2026 | C33: graduation cards 2026 | D33: GRADUATION2026 | E33: graduation cards 2026 | F33: Phrase | G33: enabled | H33: 0.56 | I33: Seasonal (Peak/Pre/Post) | J33: 1219 | K33: 6 | L33: 3.89 | M33: 0 | N33: 0 | O33: 0.0049 | P33: 0 | Q33: 0 | R33: 0.65 | S33: 0 | T33: 🆕 New | U33: 👀 Monitor
A34: 238127691910153 | B34: REWARDJAR_MIX2026_PT_reward jar | C34: Ad Group - 3/23/2026 11:51:16.760 | D34: REWARD JAR_2026 | E34: asin="B0DJ8J4WQV" | G34: enabled | H34: 0.65 | I34: Growth | J34: 217 | K34: 6 | L34: 3.79 | M34: 0 | N34: 0 | O34: 0.0276 | P34: 0 | Q34: 0 | R34: 0.63 | S34: 0 | T34: 🆕 New | U34: 👀 Monitor
A35: 257502553315874 | B35: AD_READY: B0GQBDCJJ6 | C35: Ad group - 3/23/2026 11:55:13.235 | D35: 250th USA | E35: ornament | F35: Broad | G35: enabled | H35: 0.45 | I35: Growth | J35: 998 | K35: 8 | L35: 3.55 | M35: 5.99 | N35: 1 | O35: 0.008 | P35: 0.12 | Q35: 0.5927 | R35: 0.44 | S35: 1.69 | T35: 🔴 Bleeder | U35: 📉 Decrease Bid
A36: 202664057560253 | B36: MONEYHOLDER_GRADUATION2026_AUTO | C36: Ad Group - 4/10/2026 10:10:59.421 | D36: GRADUATION2026 | E36: close-match | G36: enabled | H36: 0 | I36: Seasonal (Peak/Pre/Post) | J36: 825 | K36: 8 | L36: 3.52 | M36: 19.96 | N36: 2 | O36: 0.0097 | P36: 0.25 | Q36: 0.1764 | R36: 0.44 | S36: 5.67 | T36: 🆕 New | U36: 📈 Increase Bid
A37: 406223460061520 | B37: CROSSCAR_PSALM9111_KT_ALLGENERIC_101125 | C37: Ad Group - 11/10/2025 16:39:21.661 | D37: CROSS CAR | E37: rearview mirror cross | F37: Exact | G37: enabled | H37: 0.78 | I37: Mature/Dormant | J37: 394 | K37: 5 | L37: 3.18 | M37: 0 | N37: 0 | O37: 0.0127 | P37: 0 | Q37: 0 | R37: 0.64 | S37: 0 | T37: 🆕 New | U37: 👀 Monitor
A38: 33235065457583 | B38: ALLCARDMOTHERDAY_KT_card | C38: Ad Group - 4/13/2026 16:42:30.843 | D38: MOTHER DAY 2026 | E38: mothers day card | F38: Phrase | G38: enabled | H38: 0.56 | I38: Seasonal (Peak/Pre/Post) | J38: 320 | K38: 7 | L38: 3.18 | M38: 0 | N38: 0 | O38: 0.0219 | P38: 0 | Q38: 0 | R38: 0.45 | S38: 0 | T38: 🆕 New | U38: 👀 Monitor
A39: 216904671554832 | B39: MONEYHOLDER_GRADUATION2026_KT_ALL_PR_graduation money holder | C39: Ad Group - 4/10/2026 10:16:49.564 | D39: GRADUATION2026 | E39: graduation money holder | F39: Phrase | G39: enabled | H39: 0.5 | I39: Seasonal (Peak/Pre/Post) | J39: 242 | K39: 6 | L39: 3.15 | M39: 0 | N39: 0 | O39: 0.0248 | P39: 0 | Q39: 0 | R39: 0.52 | S39: 0 | T39: 🆕 New | U39: 👀 Monitor
A40: 72572972109732 | B40: 250TH_STICKER_SET5_KT_250th anniversary sticker | C40: Ad Group - 4/2/2026 18:37:48.155 | D40: 250th USA | E40: 250th anniversary sticker | F40: Broad | G40: enabled | H40: 0.45 | I40: Growth | J40: 870 | K40: 6 | L40: 3.13 | M40: 0 | N40: 0 | O40: 0.0069 | P40: 0 | Q40: 0 | R40: 0.52 | S40: 0 | T40: 🆕 New | U40: 👀 Monitor
...

Sheet 🔍 SEARCH TERMS
A1: Campaign Name (Informational only) | B1: Ad Group Name (Informational only) | C1: Keyword Text | D1: Match Type | E1: Customer Search Term | F1: Impressions | G1: Clicks | H1: Spend | I1: Sales | J1: Orders | K1: Click-through Rate | L1: Conversion Rate | M1: ACOS | N1: CPC | O1: ROAS | P1: Suggestion
A2: 250TH_DEVOM_DAIBANG1776-2026_KT_exact_4th of july decorations_35TRP | B2: 4th of july decorations | C2: 4th of july decorations | D2: Exact | E2: 4th of july decorations | F2: 9022 | G2: 29 | H2: 28.12 | I2: 29.94 | J2: 3 | K2: 0.0032 | L2: 0.1 | M2: 0.9392 | N2: 0.97 | O2: 1.06 | P2: ⚠️ Reduce/Monitor
A3: MONEYHOLDER_GRADUATION2026_KT_EX_graduation cards 2026 | B3: graduation cards 2026 | C3: graduation cards 2026 | D3: Exact | E3: graduation cards 2026 | F3: 4115 | G3: 16 | H3: 12.69 | I3: 9.98 | J3: 1 | K3: 0.0039 | L3: 0.06 | M3: 1.2715 | N3: 0.79 | O3: 0.79 | P3: ⚠️ Reduce/Monitor
A4: MONEYHOLDER_GRADUATION2026_KT_EX_graduation gifts for him | B4: graduation gifts for him | C4: graduation gifts for him | D4: Exact | E4: graduation gifts for him | F4: 1123 | G4: 12 | H4: 9.77 | I4: 0 | J4: 0 | K4: 0.0107 | L4: 0 | M4: 0 | N4: 0.81 | O4: 0 | P4: ➖ Negative
A5: 250TH_STICKER_SET5_KT_RANK_STIKER | B5: Ad Group - 4/13/2026 10:11:28.979 | C5: 250 anniversary usa stickers | D5: Phrase | E5: 250 anniversary usa stickers | F5: 1424 | G5: 16 | H5: 9.31 | I5: 0 | J5: 0 | K5: 0.0112 | L5: 0 | M5: 0 | N5: 0.58 | O5: 0 | P5: ➖ Negative
A6: REWARDJAR_MIX2026_reward jar | B6: Ad Group - 3/23/2026 11:42:59.947 | C6: reward jar | D6: Exact | E6: reward jar | F6: 1462 | G6: 11 | H6: 8.99 | I6: 11.98 | J6: 1 | K6: 0.0075 | L6: 0.09 | M6: 0.7504 | N6: 0.82 | O6: 1.33 | P6: ⚠️ Reduce/Monitor
A7: MONEYHOLDER_GRADUATION2026_KT_ALL_EX_graduation money holder | B7: Ad Group - 4/10/2026 10:08:29.412 | C7: graduation money holders | D7: Exact | E7: graduation money holder | F7: 636 | G7: 9 | H7: 8.02 | I7: 9.98 | J7: 1 | K7: 0.0142 | L7: 0.11 | M7: 0.8036 | N7: 0.89 | O7: 1.24 | P7: ⚠️ Reduce/Monitor
A8: 250TH_DEVOM_DAIBANG1776-2026_KT_exact_250 anniversary usa merchandise_35TRP | B8: 250 anniversary usa merchandise | C8: 250 anniversary usa merchandise | D8: Exact | E8: 250 anniversary usa merchandise | F8: 2234 | G8: 7 | H8: 6.51 | I8: 19.96 | J8: 2 | K8: 0.0031 | L8: 0.29 | M8: 0.3262 | N8: 0.93 | O8: 3.07 | P8: 👀 Monitor
A9: ONM_250TH_CHUONG_PT | B9: Ad Group - 3/25/2026 09:13:17.173 | E9: b0g24n6ckx | F9: 260 | G9: 8 | H9: 6.28 | I9: 0 | J9: 0 | K9: 0.0308 | L9: 0 | M9: 0 | N9: 0.78 | O9: 0 | P9: 👀 Monitor
A10: 250TH_STICKER_SET5_KT_Q | B10: Ad Group - 4/14/2026 17:54:19.571 | C10: usa stickers | D10: Exact | E10: usa stickers | F10: 758 | G10: 8 | H10: 5.52 | I10: 0 | J10: 0 | K10: 0.0106 | L10: 0 | M10: 0 | N10: 0.69 | O10: 0 | P10: 👀 Monitor
A11: MOTHERDAY_SIGN_TOMYMOM_KT_PR_mother day decorations | B11: MOTHERDAY_SIGN_TOMYMOM | C11: mother day decorations | D11: Phrase | E11: mothers day decorations | F11: 306 | G11: 7 | H11: 5.41 | I11: 0 | J11: 0 | K11: 0.0229 | L11: 0 | M11: 0 | N11: 0.77 | O11: 0 | P11: 👀 Monitor
A12: REWARDJAR_MIX2026_reward jars for kids | B12: Ad Group - 3/19/2026 16:06:24.106 | C12: reward jars for kids | D12: Exact | E12: reward jars for kids | F12: 1218 | G12: 9 | H12: 5.4 | I12: 0 | J12: 0 | K12: 0.0074 | L12: 0 | M12: 0 | N12: 0.6 | O12: 0 | P12: 👀 Monitor
A13: SET3_GAS_011225 | B13: Ad Group - 12/1/2025 17:27:55.919 | C13: gas cards | D13: Phrase | E13: gas card | F13: 332 | G13: 11 | H13: 4.93 | I13: 11.98 | J13: 1 | K13: 0.0331 | L13: 0.09 | M13: 0.4115 | N13: 0.45 | O13: 2.43 | P13: ⚠️ Reduce/Monitor
A14: 250TH_DEVOM_DAIBANG1776-2026_KT_broad_patriotic decorations_35TRP | B14: patriotic decorations | C14: patriotic decorations | D14: Broad | E14: patriotic decor | F14: 1228 | G14: 7 | H14: 4.69 | I14: 19.96 | J14: 2 | K14: 0.0057 | L14: 0.29 | M14: 0.235 | N14: 0.67 | O14: 4.26 | P14: ➕ Add as Exact
A15: MONEYHOLDER_SET3CARD_GAS_KTmoney gift ideas_ | B15: Ad Group - 4/13/2026 09:07:09.624 | C15: money gift ideas | D15: Exact | E15: money gift ideas | F15: 1440 | G15: 8 | H15: 4.24 | I15: 11.98 | J15: 1 | K15: 0.0056 | L15: 0.12 | M15: 0.3539 | N15: 0.53 | O15: 2.83 | P15: 👀 Monitor
A16: MONEYHOLDER_GRADUATION2026_KT_EX_2026 graduation gifts | B16: 2026 graduation gifts | C16: 2026 graduation gifts | D16: Exact | E16: 2026 graduation gifts | F16: 307 | G16: 5 | H16: 4.09 | I16: 0 | J16: 0 | K16: 0.0163 | L16: 0 | M16: 0 | N16: 0.82 | O16: 0 | P16: 👀 Monitor
A17: ONM_HUMMINGBIRD_KT-HMB_EXR_161025 | B17: Ad Group - 10/16/2025 15:47:43.916 | C17: hummingbird ornament | D17: Exact | E17: hummingbird ornaments | F17: 515 | G17: 7 | H17: 3.44 | I17: 7.98 | J17: 1 | K17: 0.0136 | L17: 0.14 | M17: 0.4311 | N17: 0.49 | O17: 2.32 | P17: ⚠️ Reduce/Monitor
A18: ONM_250TH_CHUONG_PT | B18: Ad Group - 3/25/2026 09:13:17.173 | E18: b0g364w22f | F18: 35 | G18: 4 | H18: 3.44 | I18: 41.91 | J18: 2 | K18: 0.1143 | L18: 0.5 | M18: 0.0821 | N18: 0.86 | O18: 12.18 | P18: ➕ Add as Exact
A19: CROSSCAR_PSALM9111_KT_ALLGENERIC_101125 | B19: Ad Group - 11/10/2025 16:39:21.661 | C19: rearview mirror cross | D19: Exact | E19: rearview mirror cross | F19: 388 | G19: 5 | H19: 3.18 | I19: 0 | J19: 0 | K19: 0.0129 | L19: 0 | M19: 0 | N19: 0.64 | O19: 0 | P19: 👀 Monitor
A20: MONEYHOLDER_GRADUATION2026_KT_ALL_PR_graduation money holder | B20: Ad Group - 4/10/2026 10:16:49.564 | C20: graduation money holder | D20: Phrase | E20: graduation money holder | F20: 163 | G20: 6 | H20: 3.15 | I20: 0 | J20: 0 | K20: 0.0368 | L20: 0 | M20: 0 | N20: 0.52 | O20: 0 | P20: 👀 Monitor
A21: LUCKYCHARM_4CLOVER_KT_good luck gifts | B21: Ad Group - 2/25/2026 10:03:53.033 | C21: good luck gifts | D21: Exact | E21: good luck gifts | F21: 179 | G21: 4 | H21: 3 | I21: 13.99 | J21: 1 | K21: 0.0223 | L21: 0.25 | M21: 0.2144 | N21: 0.75 | O21: 4.66 | P21: 👀 Monitor
A22: SET3_GAS_011225 | B22: Ad Group - 12/1/2025 17:27:55.919 | C22: gas cards | D22: Phrase | E22: gas cards gift cards | F22: 418 | G22: 8 | H22: 2.89 | I22: 11.98 | J22: 1 | K22: 0.0191 | L22: 0.12 | M22: 0.2412 | N22: 0.36 | O22: 4.15 | P22: 👀 Monitor
A23: MONEYHOLDER_GRADUATION2026_KT_graduation money gift ideas | B23: Ad Group - 4/13/2026 09:30:34.907 | C23: graduation money gift ideas | D23: Exact | E23: graduation money gift ideas | F23: 330 | G23: 3 | H23: 2.7 | I23: 0 | J23: 0 | K23: 0.0091 | L23: 0 | M23: 0 | N23: 0.9 | O23: 0 | P23: 👀 Monitor
A24: MONEYHOLDER_SET3CARD_GAS_KTmoney gift ideas_ | B24: Ad Group - 4/13/2026 09:07:09.624 | C24: money gift ideas | D24: Broad | E24: money gift box | F24: 62 | G24: 6 | H24: 2.63 | I24: 0 | J24: 0 | K24: 0.0968 | L24: 0 | M24: 0 | N24: 0.44 | O24: 0 | P24: 👀 Monitor
A25: MONEYHOLDER_GRADUATION2026_KT_EX_class of 2026 gifts | B25: class of 2026 gifts | C25: class of 2026 gifts | D25: Exact | E25: class of 2026 gifts | F25: 122 | G25: 3 | H25: 2.62 | I25: 0 | J25: 0 | K25: 0.0246 | L25: 0 | M25: 0 | N25: 0.87 | O25: 0 | P25: 👀 Monitor
A26: MONEYHOLDER_GRADUATION2026_KT_graduation money gift ideas | B26: Ad Group - 4/13/2026 09:30:34.907 | C26: graduation money gift ideas | D26: Broad | E26: graduation money holder | F26: 405 | G26: 4 | H26: 2.58 | I26: 0 | J26: 0 | K26: 0.0099 | L26: 0 | M26: 0 | N26: 0.64 | O26: 0 | P26: 👀 Monitor
A27: 250TH_STICKER_SET5_KT_Q | B27: Ad Group - 4/14/2026 17:54:19.571 | C27: 250 anniversary usa merchandise | D27: Exact | E27: 250 anniversary usa merchandise | F27: 226 | G27: 4 | H27: 2.54 | I27: 0 | J27: 0 | K27: 0.0177 | L27: 0 | M27: 0 | N27: 0.64 | O27: 0 | P27: 👀 Monitor
A28: REWARDJAR_MIX2026_reward jar | B28: Ad Group - 3/23/2026 11:42:59.947 | C28: reward jar | D28: Exact | E28: reward jars | F28: 34 | G28: 2 | H28: 1.81 | I28: 11.98 | J28: 1 | K28: 0.0588 | L28: 0.5 | M28: 0.1511 | N28: 0.9 | O28: 6.62 | P28: 👀 Monitor
A29: ONM_HUMMINGBIRD_KT-HMB_EXR_161025 | B29: Ad Group - 10/16/2025 15:47:43.916 | C29: hummingbird ornament | D29: Exact | E29: hummingbird ornament | F29: 441 | G29: 4 | H29: 1.77 | I29: 0 | J29: 0 | K29: 0.0091 | L29: 0 | M29: 0 | N29: 0.44 | O29: 0 | P29: 👀 Monitor
A30: REWARDJAR_MIX2026_PT_reward jar | B30: Ad Group - 3/23/2026 11:51:16.760 | E30: b0dl9kvljc | F30: 167 | G30: 3 | H30: 1.76 | I30: 0 | J30: 0 | K30: 0.018 | L30: 0 | M30: 0 | N30: 0.59 | O30: 0 | P30: 👀 Monitor
A31: ONM_HUMMINGBIRD_PT_HMB_161025 | B31: Ad Group - 10/16/2025 15:58:08.558 | E31: b08r7kydk9 | F31: 101 | G31: 6 | H31: 1.76 | I31: 0 | J31: 0 | K31: 0.0594 | L31: 0 | M31: 0 | N31: 0.29 | O31: 0 | P31: 👀 Monitor
A32: MONEYHOLDER_SET3CARD_GAS_KTmoney gift ideas_ | B32: Ad Group - 4/13/2026 09:07:09.624 | C32: money gift ideas | D32: Broad | E32: money box for cash gift | F32: 65 | G32: 4 | H32: 1.73 | I32: 0 | J32: 0 | K32: 0.0615 | L32: 0 | M32: 0 | N32: 0.43 | O32: 0 | P32: 👀 Monitor
A33: 250TH_DEVOM_DAIBANG1776-2026_KT_ALL_decor | B33: Ad Group - 4/10/2026 14:56:28.969 | C33: patriotic decorations | D33: Phrase | E33: patriotic decorations | F33: 534 | G33: 2 | H33: 1.63 | I33: 19.96 | J33: 2 | K33: 0.0037 | L33: 1 | M33: 0.0817 | N33: 0.82 | O33: 12.25 | P33: ➕ Add as Exact
A34: 250TH_DEVOM_DAIBANG1776-2026_KT_phrase_4th of july decorations_35TRP | B34: 4th of july decorations | C34: 4th of july decorations | D34: Phrase | E34: 4th of july decorations | F34: 471 | G34: 2 | H34: 1.62 | I34: 0 | J34: 0 | K34: 0.0042 | L34: 0 | M34: 0 | N34: 0.81 | O34: 0 | P34: 👀 Monitor
A35: 250TH_STICKER_SET5_KT_RANK_STIKER | B35: Ad Group - 4/13/2026 10:11:28.979 | C35: 250 anniversary usa stickers | D35: Phrase | E35: linhara 250 anniversary usa stickers | F35: 22 | G35: 2 | H35: 1.56 | I35: 5.98 | J35: 1 | K35: 0.0909 | L35: 0.5 | M35: 0.2609 | N35: 0.78 | O35: 3.83 | P35: 👀 Monitor
A36: 250TH_DEVOM_DAIBANG1776-2026_KT_ALL_decor | B36: Ad Group - 4/10/2026 14:56:28.969 | C36: fourth of july decorations | D36: Phrase | E36: fourth of july decorations | F36: 957 | G36: 2 | H36: 1.49 | I36: 9.98 | J36: 1 | K36: 0.0021 | L36: 0.5 | M36: 0.1493 | N36: 0.74 | O36: 6.7 | P36: 👀 Monitor
A37: 250TH_DEVOM_DAIBANG1776-2026_KT_ALL_decor | B37: Ad Group - 4/10/2026 14:56:28.969 | C37: patriotic decor | D37: Phrase | E37: patriotic decor | F37: 98 | G37: 2 | H37: 1.46 | I37: 0 | J37: 0 | K37: 0.0204 | L37: 0 | M37: 0 | N37: 0.73 | O37: 0 | P37: 👀 Monitor
A38: MONEYHOLDER_GRADUATION2026_KT_EX_2026 graduation gifts | B38: 2026 graduation gifts | C38: 2026 graduation gifts | D38: Exact | E38: 2026 graduation gift | F38: 13 | G38: 2 | H38: 1.46 | I38: 0 | J38: 0 | K38: 0.1538 | L38: 0 | M38: 0 | N38: 0.73 | O38: 0 | P38: 👀 Monitor
A39: SET3_GAS_011225 | B39: Ad Group - 12/1/2025 17:27:55.919 | C39: gas gift card | D39: Phrase | E39: gas gift card | F39: 478 | G39: 7 | H39: 1.37 | I39: 11.98 | J39: 1 | K39: 0.0146 | L39: 0.14 | M39: 0.1144 | N39: 0.2 | O39: 8.74 | P39: 👀 Monitor
A40: MONEYHOLDER_GRADUATION2026_KT_graduation money gift ideas | B40: Ad Group - 4/13/2026 09:30:34.907 | C40: graduation money gift ideas | D40: Broad | E40: graduation money gift | F40: 54 | G40: 2 | H40: 1.34 | I40: 0 | J40: 0 | K40: 0.037 | L40: 0 | M40: 0 | N40: 0.67 | O40: 0 | P40: 👀 Monitor
...

Sheet RAW_TS
A1: Date | B1: Campaign ID | C1: Spend | D1: Sales | E1: Date_Str
A2: 46138 | B2: 134389069964001 | C2: 2.1445506 | D2: 5.0283498 | E2: 20260426
A3: 46139 | B3: 134389069964001 | C3: 1.0089208 | D3: 5.573299 | E3: 20260427
A4: 46140 | B4: 134389069964001 | C4: 2.8150473 | D4: 5.5153624 | E4: 20260428
A5: 46141 | B5: 134389069964001 | C5: 1.8758031 | D5: 4.4947394 | E5: 20260429
A6: 46142 | B6: 134389069964001 | C6: 1.339218 | D6: 0.72452185 | E6: 20260430
A7: 46143 | B7: 134389069964001 | C7: 3.285906 | D7: 0.010238415 | E7: 20260501
A8: 46144 | B8: 134389069964001 | C8: 1.0884968 | D8: 3.886902 | E8: 20260502
A9: 46145 | B9: 134389069964001 | C9: 3.0776833 | D9: 5.4214104 | E9: 20260503
A10: 46146 | B10: 134389069964001 | C10: 1.1802133 | D10: 3.6616797 | E10: 20260504
A11: 46147 | B11: 134389069964001 | C11: 0.87487108 | D11: 3.9821846 | E11: 20260505
A12: 46148 | B12: 134389069964001 | C12: 2.9034145 | D12: 1.2845122 | E12: 20260506
A13: 46149 | B13: 134389069964001 | C13: 2.7731207 | D13: 2.8410421 | E13: 20260507
... A2115: 46151 | B2115: 49653062892987 | C2115: 0 | D2115: 0 | E2115: 20260509

Sheet 🔍 DEEP DIVE
A1: CHI TIẾT LỊCH SỬ CHI TIÊU THEO NGÀY
A2: Chọn Campaign ID: | B2: 235237638638785
A4: Date | B4: Spend | C4: Sales | D4: ACOS
A5: 46151 | B5: =SUMIFS(RAW_TS!$C:$C, RAW_TS!$B:$B, $B$2, RAW_TS!$A:$A, $A5) -> 0.9972574 | C5: =SUMIFS(RAW_TS!$D:$D, RAW_TS!$B:$B, $B$2, RAW_TS!$A:$A, $A5) -> 5.235921 | D5: =IF(C5>0, B5/C5, 0) -> 0.19046456
A6: 46150 | B6: =SUMIFS(RAW_TS!$C:$C, RAW_TS!$B:$B, $B$2, RAW_TS!$A:$A, $A6) -> 0.58481941 | C6: =SUMIFS(RAW_TS!$D:$D, RAW_TS!$B:$B, $B$2, RAW_TS!$A:$A, $A6) -> 1.8654783 | D6: =IF(C6>0, B6/C6, 0) -> 0.3134957
A7: 46149 | B7: =SUMIFS(RAW_TS!$C:$C, RAW_TS!$B:$B, $B$2, RAW_TS!$A:$A, $A7) -> 2.3919674 | C7: =SUMIFS(RAW_TS!$D:$D, RAW_TS!$B:$B, $B$2, RAW_TS!$A:$A, $A7) -> 2.757113 | D7: =IF(C7>0, B7/C7, 0) -> 0.86756234
A8: 46148 | B8: =SUMIFS(RAW_TS!$C:$C, RAW_TS!$B:$B, $B$2, RAW_TS!$A:$A, $A8) -> 2.3258243 | C8: =SUMIFS(RAW_TS!$D:$D, RAW_TS!$B:$B, $B$2, RAW_TS!$A:$A, $A8) -> 6.2040206 | D8: =IF(C8>0, B8/C8, 0) -> 0.37488985
A9: 46147 | B9: =SUMIFS(RAW_TS!$C:$C, RAW_TS!$B:$B, $B$2, RAW_TS!$A:$A, $A9) -> 2.0119205 | C9: =SUMIFS(RAW_TS!$D:$D, RAW_TS!$B:$B, $B$2, RAW_TS!$A:$A, $A9) -> 3.3262113 | D9: =IF(C9>0, B9/C9, 0) -> 0.6048685
A10: 46146 | B10: =SUMIFS(RAW_TS!$C:$C, RAW_TS!$B:$B, $B$2, RAW_TS!$A:$A, $A10) -> 2.3860922 | C10: =SUMIFS(RAW_TS!$D:$D, RAW_TS!$B:$B, $B$2, RAW_TS!$A:$A, $A10) -> 1.0495972 | D10: =IF(C10>0, B10/C10, 0) -> 2.2733408
A11: 46145 | B11: =SUMIFS(RAW_TS!$C:$C, RAW_TS!$B:$B, $B$2, RAW_TS!$A:$A, $A11) -> 0.35799909 | C11: =SUMIFS(RAW_TS!$D:$D, RAW_TS!$B:$B, $B$2, RAW_TS!$A:$A, $A11) -> 1.3554795 | D11: =IF(C11>0, B11/C11, 0) -> 0.26411251
A12: 46144 | B12: =SUMIFS(RAW_TS!$C:$C, RAW_TS!$B:$B, $B$2, RAW_TS!$A:$A, $A12) -> 2.3677628 | C12: =SUMIFS(RAW_TS!$D:$D, RAW_TS!$B:$B, $B$2, RAW_TS!$A:$A, $A12) -> 1.414358 | D12: =IF(C12>0, B12/C12, 0) -> 1.6740902
A13: 46143 | B13: =SUMIFS(RAW_TS!$C:$C, RAW_TS!$B:$B, $B$2, RAW_TS!$A:$A, $A13) -> 2.0802409 | C13: =SUMIFS(RAW_TS!$D:$D, RAW_TS!$B:$B, $B$2, RAW_TS!$A:$A, $A13) -> 2.3664797 | D13: =IF(C13>0, B13/C13, 0) -> 0.87904448
A14: 46142 | B14: =SUMIFS(RAW_TS!$C:$C, RAW_TS!$B:$B, $B$2, RAW_TS!$A:$A, $A14) -> 0.079153236 | C14: =SUMIFS(RAW_TS!$D:$D, RAW_TS!$B:$B, $B$2, RAW_TS!$A:$A, $A14) -> 4.8634316 | D14: =IF(C14>0, B14/C14, 0) -> 0.016275182
A15: 46141 | B15: =SUMIFS(RAW_TS!$C:$C, RAW_TS!$B:$B, $B$2, RAW_TS!$A:$A, $A15) -> 1.7177074 | C15: =SUMIFS(RAW_TS!$D:$D, RAW_TS!$B:$B, $B$2, RAW_TS!$A:$A, $A15) -> 3.9394602 | D15: =IF(C15>0, B15/C15, 0) -> 0.43602608
A16: 46140 | B16: =SUMIFS(RAW_TS!$C:$C, RAW_TS!$B:$B, $B$2, RAW_TS!$A:$A, $A16) -> 0.24931718 | C16: =SUMIFS(RAW_TS!$D:$D, RAW_TS!$B:$B, $B$2, RAW_TS!$A:$A, $A16) -> 4.8898801 | D16: =IF(C16>0, B16/C16, 0) -> 0.050986358
... A18: 46138 | B18: =SUMIFS(RAW_TS!$C:$C, RAW_TS!$B:$B, $B$2, RAW_TS!$A:$A, $A18) -> 0.54177914 | C18: =SUMIFS(RAW_TS!$D:$D, RAW_TS!$B:$B, $B$2, RAW_TS!$A:$A, $A18) -> 4.6703973 | D18: =IF(C18>0, B18/C18, 0) -> 0.11600279
